<?xml version="1.0"?>
<!--
  Gazebo ROS differential drive plugin demo

  Try sending commands:

    ros2 topic pub /demo/cmd_demo geometry_msgs/Twist '{linear: {x: 1.0}}' -1

    ros2 topic pub /demo/cmd_demo geometry_msgs/Twist '{angular: {z: 0.1}}' -1

  Try listening to odometry:

    ros2 topic echo /demo/odom_demo

  Try listening to TF:

    ros2 run tf2_ros tf2_echo odom_demo chassis

    ros2 run tf2_ros tf2_echo chassis right_wheel

    ros2 run tf2_ros tf2_echo chassis left_wheel
-->
<sdf version="1.6">
    <world name="default">

        <include>
            <uri>model://ground_plane</uri>
        </include>

        <include>
            <uri>model://sun</uri>
        </include>

        <model name='vehicle'>
            <pose>0 0 0.325 0 -0 0</pose>

            <link name='caster'>
                <pose>-0.957138 -0 -0.125 0 -0 0</pose>
                <inertial>
                    <mass>1</mass>
                    <inertia>
                        <ixx>0.1</ixx>
                        <ixy>0</ixy>
                        <ixz>0</ixz>
                        <iyy>0.1</iyy>
                        <iyz>0</iyz>
                        <izz>0.1</izz>
                    </inertia>
                </inertial>
                <visual name='visual'>
                    <material>
                        <!-- Wheel material -->
                        <ambient>0.1 0.1 0.1 1</ambient>
                        <diffuse>0.1 0.1 0.2 1</diffuse>
                        <specular>0 0 0 0</specular>
                        <emissive>0 0 0 1</emissive>
                    </material> <!-- End wheel material -->
                    <geometry>
                        <sphere>
                            <radius>0.2</radius>
                        </sphere>
                    </geometry>
                </visual>
                <collision name='collision'>
                    <geometry>
                        <sphere>
                            <radius>0.2</radius>
                        </sphere>
                    </geometry>
                </collision>
            </link>

            <joint name='caster_wheel' type='ball'>
                <parent>chassis</parent>
                <child>caster</child>
            </joint>

        </model>

    </world>
</sdf>