<?xml version="1.0"?>
<!--
  Gazebo ROS differential drive plugin demo

  Try sending commands:

    ros2 topic pub /demo/cmd_demo geometry_msgs/Twist '{linear: {x: 1.0}}' -1

    ros2 topic pub /demo/cmd_demo geometry_msgs/Twist '{angular: {z: 0.1}}' -1

  Try listening to odometry:

    ros2 topic echo /demo/odom_demo

  Try listening to TF:

    ros2 run tf2_ros tf2_echo odom_demo chassis

    ros2 run tf2_ros tf2_echo chassis right_wheel

    ros2 run tf2_ros tf2_echo chassis left_wheel
-->
<sdf version="1.6">
    <world name="default">

        <include>
            <uri>model://ground_plane</uri>
        </include>

        <include>
            <uri>model://sun</uri>
        </include>

        <model name='vehicle'>
            <static>false</static>
            <pose>0 0 0.325 0 -0 0</pose>
            <link name="base_footprint"/>

            <link name="imu">
                 <gravity>true</gravity>
                 <sensor name="ar_imu" type="imu">
                     <always_on>true</always_on>
                     <update_rate>100</update_rate>
                     <visualize>true</visualize>
                     <imu>
                         <orientation>
                             <x>
                                 <noise type="guassian">
                                     <mean>0.0</mean>
                                     <stddev>2e-3</stddev>
                                 </noise>
                             </x>
                             <y>
                                 <noise type="guassian">
                                     <mean>0.0</mean>
                                     <stddev>2e-3</stddev>
                                 </noise>
                             </y>
                             <z>
                                 <noise type="gaussian">
                                     <mean>0.0</mean>
                                     <stddev>2e-3</stddev>
                                 </noise>
                             </z>
                         </orientation>
                         <angular_velocity>
                            <x>
                              <noise type="gaussian">
                                <mean>0.0</mean>
                                <stddev>2e-4</stddev>
                              </noise>
                            </x>
                            <y>
                              <noise type="gaussian">
                                <mean>0.0</mean>
                                <stddev>2e-4</stddev>
                              </noise>
                            </y>
                            <z>
                              <noise type="gaussian">
                                <mean>0.0</mean>
                                <stddev>2e-4</stddev>
                              </noise>
                            </z>
                          </angular_velocity>
                          <linear_acceleration>
                            <x>
                              <noise type="gaussian">
                                <mean>0.0</mean>
                                <stddev>1.7e-2</stddev>
                              </noise>
                            </x>
                            <y>
                              <noise type="gaussian">
                                <mean>0.0</mean>
                                <stddev>1.7e-2</stddev>
                              </noise>
                            </y>
                            <z>
                              <noise type="gaussian">
                                <mean>0.0</mean>
                                <stddev>1.7e-2</stddev>
                              </noise>
                            </z>
                          </linear_acceleration>
                        </imu>
                        <plugin name="ar_imu" filename="libgazebo_ros_imu_sensor.so">
                            <initial_orientation_as_reference>false</initial_orientation_as_reference>
                            <frame_name>imu_link</frame_name>
                            <ros>
                              <namespace>/imu</namespace>
                              <remapping>~/out:=data</remapping>
                            </ros>
                          </plugin>
                 </sensor>
            </link>


            <link name="gps">
              <sensor name="gps" type="gps">
                <always_on>true</always_on>
                <update_rate>10</update_rate>
                <gps>
                  <position_sensing>
                    <horizontal>
                      <noise type="gaussian">
                        <mean>0.0</mean>
                        <stddev>1e-2</stddev>
                      </noise>
                    </horizontal>
                    <vertical>
                      <noise type="gaussian">
                        <mean>0.0</mean>
                        <stddev>1</stddev>
                      </noise>
                    </vertical>
                  </position_sensing>
                </gps>
                <plugin name="ar_gps" filename="libgazebo_ros_gps_sensor.so">
                  <ros>
                    <remapping>~/out:=gps/fix</remapping>
                  </ros>
                </plugin>
              </sensor>
            </link>

            <joint name="imu_joint" type="fixed">
              <parent>chassis</parent>
              <child>imu</child>
              <pose>0 0 0 0 0 0</pose>
            </joint>  
          
            <joint name="gps_joint" type="fixed">
              <parent>chassis</parent>
              <child>gps</child>
              <pose>0 0 0 0 0 0</pose>
            </joint>  

            <link name='caster'>
                <pose>-0.957138 -0 -0.125 0 -0 0</pose>
                <inertial>
                    <mass>1</mass>
                    <inertia>
                        <ixx>0.1</ixx>
                        <ixy>0</ixy>
                        <ixz>0</ixz>
                        <iyy>0.1</iyy>
                        <iyz>0</iyz>
                        <izz>0.1</izz>
                    </inertia>
                </inertial>
                <visual name='visual'>
                    <material>
                        <!-- Wheel material -->
                        <ambient>0.1 0.1 0.1 1</ambient>
                        <diffuse>0.1 0.1 0.2 1</diffuse>
                        <specular>0 0 0 0</specular>
                        <emissive>0 0 0 1</emissive>
                    </material> <!-- End wheel material -->
                    <geometry>
                        <sphere>
                            <radius>0.2</radius>
                        </sphere>
                    </geometry>
                </visual>
                <collision name='collision'>
                    <geometry>
                        <sphere>
                            <radius>0.2</radius>
                        </sphere>
                    </geometry>
                </collision>
            </link>

            <joint name='caster_wheel' type='ball'>
                <parent>chassis</parent>
                <child>caster</child>
            </joint>

        </model>

    </world>
</sdf>