<?xml version="1.0"?>
<!--
  Gazebo ROS differential drive plugin demo

  Try sending commands:

    ros2 topic pub /demo/cmd_demo geometry_msgs/Twist '{linear: {x: 1.0}}' -1

    ros2 topic pub /demo/cmd_demo geometry_msgs/Twist '{angular: {z: 0.1}}' -1

  Try listening to odometry:

    ros2 topic echo /demo/odom_demo

  Try listening to TF:

    ros2 run tf2_ros tf2_echo odom_demo chassis

    ros2 run tf2_ros tf2_echo chassis right_wheel

    ros2 run tf2_ros tf2_echo chassis left_wheel
-->
<sdf version="1.6">
  <world name="default">

    <include>
      <uri>model://ground_plane</uri>
    </include>

    <include>
      <uri>model://sun</uri>
    </include>

    <model name='vehicle'>
      <pose>0 0 0.325 0 -0 0</pose>

      <link name='chassis'>
        <pose>-0.2 -0 0.2 0 -0 0</pose>
        <inertial>
          <mass>1.14395</mass>
          <inertia>
            <ixx>0.126164</ixx>
            <ixy>0</ixy>
            <ixz>0</ixz>
            <iyy>0.416519</iyy>
            <iyz>0</iyz>
            <izz>0.481014</izz>
          </inertia>
        </inertial>
        <visual name='visual'>
          <geometry>
            <mesh>
              <uri>model://pioneer3at/meshes/chassis.dae</uri>
              <scale>4 4 4</scale>
              <pose>0 0 7</pose>
            </mesh>
          </geometry>
        </visual>
        <collision name='collision'>
          <geometry>
            <box>
              <size>2.01142 1 0.568726</size>
            </box>
          </geometry>
        </collision>
      </link>

      <link name='left_wheel'>
        <pose>0.554283 0.625029 -0.025 -1.5707 0 0</pose>
        <inertial>
          <mass>2</mass>
          <inertia>
            <ixx>0.145833</ixx>
            <ixy>0</ixy>
            <ixz>0</ixz>
            <iyy>0.145833</iyy>
            <iyz>0</iyz>
            <izz>0.125</izz>
          </inertia>
        </inertial>
        <visual name='visual'>
          <geometry>
            <mesh>
              <uri>model://pioneer3at/meshes/wheel.dae</uri>
              <scale>3 3 3</scale>
            </mesh>
          </geometry>
        </visual>
        <collision name='collision'>
          <geometry>
            <sphere>
              <radius>0.3</radius>
            </sphere>
          </geometry>
          <surface>
            <friction>
              <ode>
                <mu>1</mu>
                <mu2>1</mu2>
                <slip1>0</slip1>
                <slip2>0</slip2>
              </ode>
            </friction>
            <contact>
              <ode>
                <soft_cfm>0</soft_cfm>
                <soft_erp>0.2</soft_erp>
                <kp>1e+13</kp>
                <kd>1</kd>
                <max_vel>0.01</max_vel>
                <min_depth>0.01</min_depth>
              </ode>
            </contact>
          </surface>
        </collision>
      </link>

      <link name='right_wheel'>
        <pose>0.554282 -0.625029 -0.025 -1.5707 0 0</pose>
        <inertial>
          <mass>2</mass>
          <inertia>
            <ixx>0.145833</ixx>
            <ixy>0</ixy>
            <ixz>0</ixz>
            <iyy>0.145833</iyy>
            <iyz>0</iyz>
            <izz>0.125</izz>
          </inertia>
        </inertial>
        <visual name='visual'>
          <geometry>
            <mesh>
              <uri>model://pioneer3at/meshes/wheel.dae</uri>
              <scale>3 3 3</scale>
            </mesh>
          </geometry>
        </visual>
        <collision name='collision'>
          <geometry>
            <sphere>
              <radius>0.3</radius>
            </sphere>
          </geometry>
          <surface>
            <friction>
              <ode>
                <mu>1</mu>
                <mu2>1</mu2>
                <slip1>0</slip1>
                <slip2>0</slip2>
              </ode>
            </friction>
            <contact>
              <ode>
                <soft_cfm>0</soft_cfm>
                <soft_erp>0.2</soft_erp>
                <kp>1e+13</kp>
                <kd>1</kd>
                <max_vel>0.01</max_vel>
                <min_depth>0.01</min_depth>
              </ode>
            </contact>
          </surface>
        </collision>
      </link>

      <link name='caster'>
        <pose>-0.957138 -0 -0.125 0 -0 0</pose>
        <inertial>
          <mass>1</mass>
          <inertia>
            <ixx>0.1</ixx>
            <ixy>0</ixy>
            <ixz>0</ixz>
            <iyy>0.1</iyy>
            <iyz>0</iyz>
            <izz>0.1</izz>
          </inertia>
        </inertial>
        <visual name='visual'>
         <material> <!-- Wheel material -->
          <ambient>0.1 0.1 0.1 1</ambient>
          <diffuse>0.1 0.1 0.2 1</diffuse>
          <specular>0 0 0 0</specular>
          <emissive>0 0 0 1</emissive>
        </material> <!-- End wheel material -->
          <geometry>
            <sphere>
              <radius>0.2</radius>
            </sphere>
          </geometry>
        </visual>
        <collision name='collision'>
          <geometry>
            <sphere>
              <radius>0.2</radius>
            </sphere>
          </geometry>
        </collision>
      </link>
       <!-- Add the laser range finder -->
       <link name="laser_link">
        <inertial>
          <!-- Mass of the laser range finder in kg -->
          <mass>0.1</mass>
        </inertial>
        <!-- Position is towards the front of the robot -->
        <!-- Laser finder is mounted on top -->
        <pose>0.15 0 0.70 0 0 0</pose>
        

        <!-- Add a mesh to make it more visually appealing -->
        <visual name="visual">
          <geometry>
            <mesh>
              <uri>model://hokuyo/meshes/hokuyo.dae</uri>
            </mesh>
          </geometry>
        </visual>
        
        <!-- Collision properties of the base of the laser range finder-->
        <collision name="collision-base">
          <pose>0 0 -0.0145 0 0 0</pose>
          <geometry>
            <box>
              <size>0.05 0.05 0.041</size>
            </box>
          </geometry>
        </collision>
        <!-- Collision properties of the top of the laser range finder-->
        <collision name="collision-top">
          <pose>0 0 0.0205 0 0 0</pose>
          <geometry>
            <cylinder>
              <radius>0.021</radius>
              <length>0.029</length>
            </cylinder>
          </geometry>
        </collision>
        
        <!-- Describes the type and properties of the sensor -->
  <sensor name="laser" type="ray">
    <pose>0.01 0 0.0175 0 -0 0</pose>
          <ray>
            <scan>
              <horizontal>
                <samples>181</samples>
                <resolution>1</resolution>
                <min_angle>-1.57080</min_angle>
                <max_angle>1.57080</max_angle>
              </horizontal>
            </scan>
            <range>
              <min>0.08</min>
              <max>10</max>
              <resolution>0.05</resolution>
            </range>
          </ray>
          <always_on>1</always_on>
          <update_rate>10</update_rate>
          <visualize>true</visualize>

          <plugin name='laser' filename='libgazebo_ros_ray_sensor.so'>
            <ros>
              <namespace>/demo</namespace>
              <argument>--ros-args --remap ~/out:=scan</argument>
            </ros>
            <output_type>sensor_msgs/LaserScan</output_type>
          </plugin>
  </sensor>
      </link>

      <link name='Wall_0'>
              <collision name='Wall_0_Collision'>
                <geometry>
                  <box>
                    <size>6.75 0.15 2.5</size>
                  </box>
                </geometry>
                <pose>5 5 1.25 0 -0 0</pose>
              </collision>
              <visual name='Wall_0_Visual'>
                <pose>0 0 1.25 0 -0 0</pose>
                <geometry>
                  <box>
                    <size>6.75 0.15 2.5</size>
                  </box>
                </geometry>
                <material>
                  <script>
                    <uri>file://media/materials/scripts/gazebo.material</uri>
                    <name>Gazebo/Grey</name>
                  </script>
                  <ambient>1 1 1 1</ambient>
                </material>
                <meta>
                  <layer>0</layer>
                </meta>
              </visual>
              <pose>1.45828 -0.30859 0 0 -0 0</pose>
            </link>
            <link name='Wall_1'>
              <collision name='Wall_1_Collision'>
                <geometry>
                  <box>
                    <size>0.16 0.15 2.5</size>
                  </box>
                </geometry>
                <pose>0 0 1.25 0 -0 0</pose>
              </collision>
              <visual name='Wall_1_Visual'>
                <pose>0 0 1.25 0 -0 0</pose>
                <geometry>
                  <box>
                    <size>0.16 0.15 2.5</size>
                  </box>
                </geometry>
                <material>
                  <script>
                    <uri>file://media/materials/scripts/gazebo.material</uri>
                    <name>Gazebo/Grey</name>
                  </script>
                  <ambient>1 1 1 1</ambient>
                </material>
                <meta>
                  <layer>0</layer>
                </meta>
              </visual>
              <pose>4.76328 -0.30859 0 0 -0 0</pose>
            </link>
            <link name='Wall_12'>
              <collision name='Wall_12_Collision'>
                <geometry>
                  <box>
                    <size>20.25 0.15 2.5</size>
                  </box>
                </geometry>
                <pose>0 0 1.25 0 -0 0</pose>
              </collision>
              <visual name='Wall_12_Visual'>
                <pose>0 0 1.25 0 -0 0</pose>
                <geometry>
                  <box>
                    <size>20.25 0.15 2.5</size>
                  </box>
                </geometry>
                <material>
                  <script>
                    <uri>file://media/materials/scripts/gazebo.material</uri>
                    <name>Gazebo/Grey</name>
                  </script>
                  <ambient>1 1 1 1</ambient>
                </material>
                <meta>
                  <layer>0</layer>
                </meta>
              </visual>
              <pose>-0.223153 -11.2513 0 0 -0 0</pose>
            </link>
            <link name='Wall_14'>
              <collision name='Wall_14_Collision'>
                <geometry>
                  <box>
                    <size>21.25 0.15 2.5</size>
                  </box>
                </geometry>
                <pose>0 0 1.25 0 -0 0</pose>
              </collision>
              <visual name='Wall_14_Visual'>
                <pose>0 0 1.25 0 -0 0</pose>
                <geometry>
                  <box>
                    <size>21.25 0.15 2.5</size>
                  </box>
                </geometry>
                <material>
                  <script>
                    <uri>file://media/materials/scripts/gazebo.material</uri>
                    <name>Gazebo/Grey</name>
                  </script>
                  <ambient>1 1 1 1</ambient>
                </material>
                <meta>
                  <layer>0</layer>
                </meta>
              </visual>
              <pose>-10.3084 0.7013 0 0 -0 1.5708</pose>
            </link>
            <link name='Wall_15'>
              <collision name='Wall_15_Collision'>
                <geometry>
                  <box>
                    <size>20.75 0.15 2.5</size>
                  </box>
                </geometry>
                <pose>0 0 1.25 0 -0 0</pose>
              </collision>
              <visual name='Wall_15_Visual'>
                <pose>0 0 1.25 0 -0 0</pose>
                <geometry>
                  <box>
                    <size>20.75 0.15 2.5</size>
                  </box>
                </geometry>
                <material>
                  <script>
                    <uri>file://media/materials/scripts/gazebo.material</uri>
                    <name>Gazebo/Grey</name>
                  </script>
                  <ambient>1 1 1 1</ambient>
                </material>
                <meta>
                  <layer>0</layer>
                </meta>
              </visual>
              <pose>-0.008427 11.2513 0 0 -0 0</pose>
            </link>
            <link name='Wall_16'>
              <collision name='Wall_16_Collision'>
                <geometry>
                  <box>
                    <size>22.25 0.15 2.5</size>
                  </box>
                </geometry>
                <pose>0 0 1.25 0 -0 0</pose>
              </collision>
              <visual name='Wall_16_Visual'>
                <pose>0 0 1.25 0 -0 0</pose>
                <geometry>
                  <box>
                    <size>22.25 0.15 2.5</size>
                  </box>
                </geometry>
                <material>
                  <script>
                    <uri>file://media/materials/scripts/gazebo.material</uri>
                    <name>Gazebo/Grey</name>
                  </script>
                  <ambient>1 1 1 1</ambient>
                </material>
                <meta>
                  <layer>0</layer>
                </meta>
              </visual>
              <pose>10.2916 0.2013 0 0 -0 -1.5708</pose>
            </link>
            <link name='Wall_17'>
              <collision name='Wall_17_Collision'>
                <geometry>
                  <box>
                    <size>0.5 0.15 2.5</size>
                  </box>
                </geometry>
                <pose>0 0 1.25 0 -0 0</pose>
              </collision>
              <visual name='Wall_17_Visual'>
                <pose>0 0 1.25 0 -0 0</pose>
                <geometry>
                  <box>
                    <size>0.5 0.15 2.5</size>
                  </box>
                </geometry>
                <material>
                  <script>
                    <uri>file://media/materials/scripts/gazebo.material</uri>
                    <name>Gazebo/Grey</name>
                  </script>
                  <ambient>1 1 1 1</ambient>
                </material>
                <meta>
                  <layer>0</layer>
                </meta>
              </visual>
              <pose>10.2463 -11.0177 0 0 -0 -1.8326</pose>
            </link>
            <link name='Wall_18'>
              <collision name='Wall_18_Collision'>
                <geometry>
                  <box>
                    <size>2 0.15 2.5</size>
                  </box>
                </geometry>
                <pose>0 0 1.25 0 -0 0</pose>
              </collision>
              <visual name='Wall_18_Visual'>
                <pose>0 0 1.25 0 -0 0</pose>
                <geometry>
                  <box>
                    <size>2 0.15 2.5</size>
                  </box>
                </geometry>
                <material>
                  <script>
                    <uri>file://media/materials/scripts/gazebo.material</uri>
                    <name>Gazebo/Grey</name>
                  </script>
                  <ambient>1 1 1 1</ambient>
                </material>
                <meta>
                  <layer>0</layer>
                </meta>
              </visual>
              <pose>9.27599 -11.1868 0 0 -0 3.14159</pose>
            </link>
            <link name='Wall_19'>
              <collision name='Wall_19_Collision'>
                <geometry>
                  <box>
                    <size>18.75 0.15 2.5</size>
                  </box>
                </geometry>
                <pose>0 0 1.25 0 -0 0</pose>
              </collision>
              <visual name='Wall_19_Visual'>
                <pose>0 0 1.25 0 -0 0</pose>
                <geometry>
                  <box>
                    <size>18.75 0.15 2.5</size>
                  </box>
                </geometry>
                <material>
                  <script>
                    <uri>file://media/materials/scripts/gazebo.material</uri>
                    <name>Gazebo/Grey</name>
                  </script>
                  <ambient>1 1 1 1</ambient>
                </material>
                <meta>
                  <layer>0</layer>
                </meta>
              </visual>
              <pose>-0.949013 -11.1868 0 0 -0 3.14159</pose>
            </link>
            <link name='Wall_2'>
              <collision name='Wall_2_Collision'>
                <geometry>
                  <box>
                    <size>2.75 0.15 2.5</size>
                  </box>
                </geometry>
                <pose>0 0 1.25 0 -0 0</pose>
              </collision>
              <visual name='Wall_2_Visual'>
                <pose>0 0 1.25 0 -0 0</pose>
                <geometry>
                  <box>
                    <size>2.75 0.15 2.5</size>
                  </box>
                </geometry>
                <material>
                  <script>
                    <uri>file://media/materials/scripts/gazebo.material</uri>
                    <name>Gazebo/Grey</name>
                  </script>
                  <ambient>1 1 1 1</ambient>
                </material>
                <meta>
                  <layer>0</layer>
                </meta>
              </visual>
              <pose>4.76828 -1.60859 0 0 -0 -1.5708</pose>
            </link>
            <link name='Wall_20'>
              <collision name='Wall_20_Collision'>
                <geometry>
                  <box>
                    <size>2.25 0.15 2.5</size>
                  </box>
                </geometry>
                <pose>0 0 1.25 0 -0 0</pose>
              </collision>
              <visual name='Wall_20_Visual'>
                <pose>0 0 1.25 0 -0 0</pose>
                <geometry>
                  <box>
                    <size>2.25 0.15 2.5</size>
                  </box>
                </geometry>
                <material>
                  <script>
                    <uri>file://media/materials/scripts/gazebo.material</uri>
                    <name>Gazebo/Grey</name>
                  </script>
                  <ambient>1 1 1 1</ambient>
                </material>
                <meta>
                  <layer>0</layer>
                </meta>
              </visual>
              <pose>-10.249 -10.1368 0 0 -0 1.5708</pose>
            </link>
            <link name='Wall_23'>
              <collision name='Wall_23_Collision'>
                <geometry>
                  <box>
                    <size>2.5 0.15 2.5</size>
                  </box>
                </geometry>
                <pose>0 0 1.25 0 -0 0</pose>
              </collision>
              <visual name='Wall_23_Visual'>
                <pose>0 0 1.25 0 -0 0</pose>
                <geometry>
                  <box>
                    <size>2.5 0.15 2.5</size>
                  </box>
                </geometry>
                <material>
                  <script>
                    <uri>file://media/materials/scripts/gazebo.material</uri>
                    <name>Gazebo/Grey</name>
                  </script>
                  <ambient>1 1 1 1</ambient>
                </material>
                <meta>
                  <layer>0</layer>
                </meta>
              </visual>
              <pose>-1.66575 6.18639 0 0 -0 -1.5708</pose>
            </link>
            <link name='Wall_24'>
              <collision name='Wall_24_Collision'>
                <geometry>
                  <box>
                    <size>1.5 0.15 2.5</size>
                  </box>
                </geometry>
                <pose>0 0 1.25 0 -0 0</pose>
              </collision>
              <visual name='Wall_24_Visual'>
                <pose>0 0 1.25 0 -0 0</pose>
                <geometry>
                  <box>
                    <size>1.5 0.15 2.5</size>
                  </box>
                </geometry>
                <material>
                  <script>
                    <uri>file://media/materials/scripts/gazebo.material</uri>
                    <name>Gazebo/Grey</name>
                  </script>
                  <ambient>1 1 1 1</ambient>
                </material>
                <meta>
                  <layer>0</layer>
                </meta>
              </visual>
              <pose>-0.990749 5.01139 0 0 -0 0</pose>
            </link>
            <link name='Wall_25'>
              <collision name='Wall_25_Collision'>
                <geometry>
                  <box>
                    <size>0.16 0.15 2.5</size>
                  </box>
                </geometry>
                <pose>0 0 1.25 0 -0 0</pose>
              </collision>
              <visual name='Wall_25_Visual'>
                <pose>0 0 1.25 0 -0 0</pose>
                <geometry>
                  <box>
                    <size>0.16 0.15 2.5</size>
                  </box>
                </geometry>
                <material>
                  <script>
                    <uri>file://media/materials/scripts/gazebo.material</uri>
                    <name>Gazebo/Grey</name>
                  </script>
                  <ambient>1 1 1 1</ambient>
                </material>
                <meta>
                  <layer>0</layer>
                </meta>
              </visual>
              <pose>-0.310749 5.01139 0 0 -0 0</pose>
            </link>
            <link name='Wall_26'>
              <collision name='Wall_26_Collision'>
                <geometry>
                  <box>
                    <size>2.75 0.15 2.5</size>
                  </box>
                </geometry>
                <pose>0 0 1.25 0 -0 0</pose>
              </collision>
              <visual name='Wall_26_Visual'>
                <pose>0 0 1.25 0 -0 0</pose>
                <geometry>
                  <box>
                    <size>2.75 0.15 2.5</size>
                  </box>
                </geometry>
                <material>
                  <script>
                    <uri>file://media/materials/scripts/gazebo.material</uri>
                    <name>Gazebo/Grey</name>
                  </script>
                  <ambient>1 1 1 1</ambient>
                </material>
                <meta>
                  <layer>0</layer>
                </meta>
              </visual>
              <pose>-0.305749 6.31139 0 0 -0 1.5708</pose>
            </link>
            <link name='Wall_27'>
              <collision name='Wall_27_Collision'>
                <geometry>
                  <box>
                    <size>1.75 0.15 2.5</size>
                  </box>
                </geometry>
                <pose>0 0 1.25 0 -0 0</pose>
              </collision>
              <visual name='Wall_27_Visual'>
                <pose>0 0 1.25 0 -0 0</pose>
                <geometry>
                  <box>
                    <size>1.75 0.15 2.5</size>
                  </box>
                </geometry>
                <material>
                  <script>
                    <uri>file://media/materials/scripts/gazebo.material</uri>
                    <name>Gazebo/Grey</name>
                  </script>
                  <ambient>1 1 1 1</ambient>
                </material>
                <meta>
                  <layer>0</layer>
                </meta>
              </visual>
              <pose>-1.07849 7.40433 0 0 -0 -2.87979</pose>
            </link>
            <link name='Wall_29'>
              <collision name='Wall_29_Collision'>
                <geometry>
                  <box>
                    <size>5.58069 0.15 2.5</size>
                  </box>
                </geometry>
                <pose>0 0 1.25 0 -0 0</pose>
              </collision>
              <visual name='Wall_29_Visual'>
                <pose>0 0 1.25 0 -0 0</pose>
                <geometry>
                  <box>
                    <size>5.58069 0.15 2.5</size>
                  </box>
                </geometry>
                <material>
                  <script>
                    <uri>file://media/materials/scripts/gazebo.material</uri>
                    <name>Gazebo/Grey</name>
                  </script>
                  <ambient>1 1 1 1</ambient>
                </material>
                <meta>
                  <layer>0</layer>
                </meta>
              </visual>
              <pose>-4.80591 -1.35777 0 0 -0 -0.938765</pose>
            </link>
            <link name='Wall_31'>
              <collision name='Wall_31_Collision'>
                <geometry>
                  <box>
                    <size>4.5 0.15 2.5</size>
                  </box>
                </geometry>
                <pose>0 0 1.25 0 -0 0</pose>
              </collision>
              <visual name='Wall_31_Visual'>
                <pose>0 0 1.25 0 -0 0</pose>
                <geometry>
                  <box>
                    <size>4.5 0.15 2.5</size>
                  </box>
                </geometry>
                <material>
                  <script>
                    <uri>file://media/materials/scripts/gazebo.material</uri>
                    <name>Gazebo/Grey</name>
                  </script>
                  <ambient>1 1 1 1</ambient>
                </material>
                <meta>
                  <layer>0</layer>
                </meta>
              </visual>
              <pose>5.01995 -6.76237 0 0 -0 0.785398</pose>
            </link>
            <link name='Wall_4'>
              <collision name='Wall_4_Collision'>
                <geometry>
                  <box>
                    <size>0.3 0.15 2.5</size>
                  </box>
                </geometry>
                <pose>0 0 1.25 0 -0 0</pose>
              </collision>
              <visual name='Wall_4_Visual'>
                <pose>0 0 1.25 0 -0 0</pose>
                <geometry>
                  <box>
                    <size>0.3 0.15 2.5</size>
                  </box>
                </geometry>
                <material>
                  <script>
                    <uri>file://media/materials/scripts/gazebo.material</uri>
                    <name>Gazebo/Grey</name>
                  </script>
                  <ambient>1 1 1 1</ambient>
                </material>
                <meta>
                  <layer>0</layer>
                </meta>
              </visual>
              <pose>-3.12672 -3.54859 0 0 -0 0</pose>
            </link>
            <link name='Wall_5'>
              <collision name='Wall_5_Collision'>
                <geometry>
                  <box>
                    <size>1.25 0.15 2.5</size>
                  </box>
                </geometry>
                <pose>0 0 1.25 0 -0 0</pose>
              </collision>
              <visual name='Wall_5_Visual'>
                <pose>0 0 1.25 0 -0 0</pose>
                <geometry>
                  <box>
                    <size>1.25 0.15 2.5</size>
                  </box>
                </geometry>
                <material>
                  <script>
                    <uri>file://media/materials/scripts/gazebo.material</uri>
                    <name>Gazebo/Grey</name>
                  </script>
                  <ambient>1 1 1 1</ambient>
                </material>
                <meta>
                  <layer>0</layer>
                </meta>
              </visual>
              <pose>-2.50172 -3.54859 0 0 -0 0</pose>
            </link>


      <joint name='left_wheel_joint' type='revolute'>
        <parent>chassis</parent>
        <child>left_wheel</child>
        <axis>
          <xyz>0 0 1</xyz>
          <limit>
            <lower>-1.79769e+308</lower>
            <upper>1.79769e+308</upper>
          </limit>
        </axis>
      </joint>

      <joint name='right_wheel_joint' type='revolute'>
        <parent>chassis</parent>
        <child>right_wheel</child>
        <axis>
          <xyz>0 0 1</xyz>
          <limit>
            <lower>-1.79769e+308</lower>
            <upper>1.79769e+308</upper>
          </limit>
        </axis>
      </joint>

      <!-- Connect laser range finder to the robot's body -->
      <joint type="fixed" name="laser_joint">
        <child>laser_link</child>
          <parent>chassis</parent>
      </joint>

      <joint name='caster_wheel' type='ball'>
        <parent>chassis</parent>
        <child>caster</child>
      </joint>

      <plugin name='diff_drive' filename='libgazebo_ros_diff_drive.so'>

        <ros>
          <namespace>/demo</namespace>
          <remapping>cmd_vel:=cmd_demo</remapping>
          <remapping>odom:=odom_demo</remapping>
        </ros>

        <!-- wheels -->
        <left_joint>left_wheel_joint</left_joint>
        <right_joint>right_wheel_joint</right_joint>

        <!-- kinematics -->
        <wheel_separation>1.25</wheel_separation>
        <wheel_diameter>0.6</wheel_diameter>

        <!-- limits -->
        <max_wheel_torque>20</max_wheel_torque>
        <max_wheel_acceleration>1.0</max_wheel_acceleration>

        <!-- output -->
        <publish_odom>true</publish_odom>
        <publish_odom_tf>true</publish_odom_tf>
        <publish_wheel_tf>true</publish_wheel_tf>

        <odometry_frame>odom_demo</odometry_frame>
        <robot_base_frame>chassis</robot_base_frame>

      </plugin>

    </model>

  </world>
</sdf>