<?xml version="1.0"?>
<!--
  Gazebo ROS differential drive plugin demo
  Try sending commands:
    ros2 topic pub /demo/cmd_demo geometry_msgs/Twist '{linear: {x: 1.0}}' -1
    ros2 topic pub /demo/cmd_demo geometry_msgs/Twist '{angular: {z: 0.1}}' -1
  Try listening to odometry:
    ros2 topic echo /demo/odom_demo
  Try listening to TF:
    ros2 run tf2_ros tf2_echo odom_demo chassis
    ros2 run tf2_ros tf2_echo chassis right_wheel
    ros2 run tf2_ros tf2_echo chassis left_wheel
-->
<sdf version="1.6">
  <world name="default">

    <include>
      <uri>model://ground_plane</uri>
    </include>

    <include>
      <uri>model://sun</uri>
    </include>

    <model name='vehicle'>
      <pose>0 0 0.325 0 -0 0</pose>

      <link name='chassis'>
        <pose>-0.151427 -0 0.175 0 -0 0</pose>
        <inertial>
          <mass>1.14395</mass>
          <inertia>
            <ixx>0.126164</ixx>
            <ixy>0</ixy>
            <ixz>0</ixz>
            <iyy>0.416519</iyy>
            <iyz>0</iyz>
            <izz>0.481014</izz>
          </inertia>
        </inertial>
        <visual name='visual'>
          <geometry>
            <box>
              <size>2.01142 1 0.568726</size>
            </box>
          </geometry>
        </visual>
        <collision name='collision'>
          <geometry>
            <box>
              <size>2.01142 1 0.568726</size>
            </box>
          </geometry>
        </collision>
      </link>

      <link name='left_wheel'>
        <pose>0.554283 0.625029 -0.025 -1.5707 0 0</pose>
        <inertial>
          <mass>2</mass>
          <inertia>
            <ixx>0.145833</ixx>
            <ixy>0</ixy>
            <ixz>0</ixz>
            <iyy>0.145833</iyy>
            <iyz>0</iyz>
            <izz>0.125</izz>
          </inertia>
        </inertial>
        <visual name="visual">
          <geometry>
            <cylinder>
              <radius>.4</radius>
              <length>.1</length>
            </cylinder>
          </geometry>
        </visual>
        <collision name="collision">
          <geometry>
            <cylinder>
              <radius>.4</radius>
              <length>.1</length>
            </cylinder>
          </geometry>
          <surface>
            <friction>
              <ode>
                <mu>1</mu>
                <mu2>1</mu2>
                <slip1>0</slip1>
                <slip2>0</slip2>
              </ode>
            </friction>
            <contact>
              <ode>
                <soft_cfm>0</soft_cfm>
                <soft_erp>0.2</soft_erp>
                <kp>1e+13</kp>
                <kd>1</kd>
                <max_vel>0.01</max_vel>
                <min_depth>0.01</min_depth>
              </ode>
            </contact>
          </surface>
        </collision>
      </link>

      <link name='right_wheel'>
        <pose>0.554282 -0.625029 -0.025 -1.5707 0 0</pose>
        <inertial>
          <mass>2</mass>
          <inertia>
            <ixx>0.145833</ixx>
            <ixy>0</ixy>
            <ixz>0</ixz>
            <iyy>0.145833</iyy>
            <iyz>0</iyz>
            <izz>0.125</izz>
          </inertia>
        </inertial>
        <visual name="visual">
          <geometry>
            <cylinder>
              <radius>.4</radius>
              <length>.1</length>
            </cylinder>
          </geometry>
        </visual>
        <collision name="collision">
          <geometry>
            <cylinder>
              <radius>.4</radius>
              <length>.1</length>
            </cylinder>
          </geometry>
          <surface>
            <friction>
              <ode>
                <mu>1</mu>
                <mu2>1</mu2>
                <slip1>0</slip1>
                <slip2>0</slip2>
              </ode>
            </friction>
            <contact>
              <ode>
                <soft_cfm>0</soft_cfm>
                <soft_erp>0.2</soft_erp>
                <kp>1e+13</kp>
                <kd>1</kd>
                <max_vel>0.01</max_vel>
                <min_depth>0.01</min_depth>
              </ode>
            </contact>
          </surface>
        </collision>
      </link>
        <!---
         <param1: Adjusts the wheel alignment parallel to the body>
         <param2: Adjusts the distance between the chassis and the wheel>
         <param3: Adjusts the height of the wheel link>
        -->
      <link name='right_rear_wheel'>
        <pose>-0.954282 -0.625029 0.025 -1.5707 0 0</pose>
        <inertial>
          <mass>2</mass>
          <inertia>
            <ixx>0.145833</ixx>
            <ixy>0</ixy>
            <ixz>0</ixz>
            <iyy>0.145833</iyy>
            <iyz>0</iyz>
            <izz>0.125</izz>
          </inertia>
        </inertial>
        <visual name="visual">
          <geometry>
            <cylinder>
              <radius>.4</radius>
              <length>.1</length>
            </cylinder>
          </geometry>
        </visual>
        <collision name="collision">
          <geometry>
            <cylinder>
              <radius>.4</radius>
              <length>.1</length>
            </cylinder>
          </geometry>
          <surface>
            <friction>
              <ode>
                <mu>1</mu>
                <mu2>1</mu2>
                <slip1>0</slip1>
                <slip2>0</slip2>
              </ode>
            </friction>
            <contact>
              <ode>
                <soft_cfm>0</soft_cfm>
                <soft_erp>0.2</soft_erp>
                <kp>1e+13</kp>
                <kd>1</kd>
                <max_vel>0.01</max_vel>
                <min_depth>0.01</min_depth>
              </ode>
            </contact>
          </surface>
        </collision>
      </link>

      <link name='left_rear_wheel'>
        <pose>-0.954282 0.625029 -0.025 -1.5707 0 0</pose>
        <inertial>
          <mass>2</mass>
          <inertia>
            <ixx>0.145833</ixx>
            <ixy>0</ixy>
            <ixz>0</ixz>
            <iyy>0.145833</iyy>
            <iyz>0</iyz>
            <izz>0.125</izz>
          </inertia>
        </inertial>
        <visual name="visual">
          <geometry>
            <cylinder>
              <radius>.4</radius>
              <length>.1</length>
            </cylinder>
          </geometry>
        </visual>
        <collision name="collision">
          <geometry>
            <cylinder>
              <radius>.4</radius>
              <length>.1</length>
            </cylinder>
          </geometry>
          <surface>
            <friction>
              <ode>
                <mu>1</mu>
                <mu2>1</mu2>
                <slip1>0</slip1>
                <slip2>0</slip2>
              </ode>
            </friction>
            <contact>
              <ode>
                <soft_cfm>0</soft_cfm>
                <soft_erp>0.2</soft_erp>
                <kp>1e+13</kp>
                <kd>1</kd>
                <max_vel>0.01</max_vel>
                <min_depth>0.01</min_depth>
              </ode>
            </contact>
          </surface>
        </collision>
      </link>
      <!-- Add the laser range finder -->
            <link name="laser_link">
              <inertial>
                <!-- Mass of the laser range finder in kg -->
                <mass>0.1</mass>
              </inertial>
              <!-- Position is towards the front of the robot -->
              <!-- Laser finder is mounted on top -->
              <pose>0.35 0 0.30 0 0 0</pose>

              <!-- Add a mesh to make it more visually appealing -->
              <visual name="visual">
                <geometry>
                  <mesh>
                    <uri>model://hokuyo/meshes/hokuyo.dae</uri>
                  </mesh>
                </geometry>
              </visual>

              <!-- Collision properties of the base of the laser range finder-->
              <collision name="collision-base">
                <pose>0 0 -0.0145 0 0 0</pose>
                <geometry>
                  <box>
                    <size>0.05 0.05 0.041</size>
                  </box>
                </geometry>
              </collision>
              <!-- Collision properties of the top of the laser range finder-->
              <collision name="collision-top">
                <pose>0 0 0.0205 0 0 0</pose>
                <geometry>
                  <cylinder>
                    <radius>0.021</radius>
                    <length>0.029</length>
                  </cylinder>
                </geometry>
              </collision>

              <!-- Describes the type and properties of the sensor -->
        <sensor name="laser" type="ray">
          <pose>0.01 0 0.0175 0 -0 0</pose>
                <ray>
                  <scan>
                    <horizontal>
                      <samples>181</samples>
                      <resolution>1</resolution>
                      <min_angle>-1.57080</min_angle>
                      <max_angle>1.57080</max_angle>
                    </horizontal>
                  </scan>
                  <range>
                    <min>0.08</min>
                    <max>10</max>
                    <resolution>0.05</resolution>
                  </range>
                </ray>
                <always_on>1</always_on>
                <update_rate>10</update_rate>
                <visualize>true</visualize>

                <plugin name='laser' filename='libgazebo_ros_ray_sensor.so'>
                  <ros>
                    <namespace>/demo</namespace>
                    <argument>--ros-args --remap ~/out:=scan</argument>
                  </ros>
                  <output_type>sensor_msgs/LaserScan</output_type>
                </plugin>
        </sensor>
            </link>

      <joint name='left_wheel_joint' type='revolute'>
        <parent>chassis</parent>
        <child>left_wheel</child>
        <axis>
          <xyz>0 0 1</xyz>
          <limit>
            <lower>-1.79769e+308</lower>
            <upper>1.79769e+308</upper>
          </limit>
        </axis>
      </joint>

      <joint name='right_wheel_joint' type='revolute'>
        <parent>chassis</parent>
        <child>right_wheel</child>
        <axis>
          <xyz>0 0 1</xyz>
          <limit>
            <lower>-1.79769e+308</lower>
            <upper>1.79769e+308</upper>
          </limit>
        </axis>
      </joint>

      <!-- <joint type="fixed" name="laser_joint">
        <child>laser_link</child>
          <parent>chassis</parent>
      </joint>  -->

      <joint type="revolute" name="right_wheel_hinge">
        <pose>0 0 0.03 0 0 0</pose>
        <child>right_rear_wheel</child>
        <parent>chassis</parent>
        <axis>
          <xyz>0 0 3</xyz>
        </axis>
        <limit>
          <lower>-1.79769e+308</lower>
          <upper>1.79769e+308</upper>
        </limit>
      </joint>

      <joint type="revolute" name="left_wheel_hinge">
        <pose>0 0 0.03 0 0 0</pose>
        <child>left_rear_wheel</child>
        <parent>chassis</parent>
        <axis>
          <xyz>0 0 3</xyz>
        </axis>
        <limit>
          <lower>-1.79769e+308</lower>
          <upper>1.79769e+308</upper>
        </limit>
      </joint>

      <plugin name='diff_drive' filename='libgazebo_ros_diff_drive.so'>

        <ros>
          <namespace>/demo</namespace>
          <argument>cmd_vel:=cmd_demo</argument>
          <argument>odom:=odom_demo</argument>
        </ros>

        <!-- wheels -->
        <!-- <left_joint>left_wheel_joint</left_joint> -->
        <!-- <right_joint>right_wheel_joint</right_joint> -->
        <right_rear_joint>right_wheel_hinge</right_rear_joint>
        <left_rear_joint>left_wheel_hinge</left_rear_joint>

        <!-- kinematics -->
        <wheel_separation>1.25</wheel_separation>
        <wheel_diameter>0.6</wheel_diameter>

        <!-- limits -->
        <max_wheel_torque>20</max_wheel_torque>
        <max_wheel_acceleration>1.0</max_wheel_acceleration>

        <!-- output -->
        <publish_odom>true</publish_odom>
        <publish_odom_tf>true</publish_odom_tf>
        <publish_wheel_tf>true</publish_wheel_tf>

        <odometry_frame>odom_demo</odometry_frame>
        <robot_base_frame>chassis</robot_base_frame>

      </plugin>

    </model>

  </world>
</sdf>