<?xml version="1.0"?>
  <sdf version="1.6">
    <world name="default">

      <include>
        <uri>model://ground_plane</uri>
      </include>

      <include>
        <uri>model://sun</uri>
      </include>

      <model name='vehicle'>
        <pose>0 0 0.325 0 -0 0</pose>

        <link name='chassis'>
          <pose>-0.151427 -0 0.175 0 -0 0</pose>
          <inertial>
            <mass>1.14395</mass>
            <inertia>
              <ixx>0.126164</ixx>
              <ixy>0</ixy>
              <ixz>0</ixz>
              <iyy>0.416519</iyy>
              <iyz>0</iyz>
              <izz>0.481014</izz>
            </inertia>
          </inertial>
          <visual name='visual'>
            <geometry>
              <box>
                <size>2.01142 1 0.568726</size>
              </box>
            </geometry>
          </visual>
          <collision name='collision'>
            <geometry>
              <box>
                <size>2.01142 1 0.568726</size>
              </box>
            </geometry>
          </collision>
        </link>

        <link name='left_wheel0'>
          <pose>0.554283 0.625029 -0.025 -1.5707 0 0</pose>
          <inertial>
            <mass>2</mass>
            <inertia>
              <ixx>0.145833</ixx>
              <ixy>0</ixy>
              <ixz>0</ixz>
              <iyy>0.145833</iyy>
              <iyz>0</iyz>
              <izz>0.125</izz>
            </inertia>
          </inertial>
          <visual name='visual'>
            <geometry>
              <sphere>
                <radius>0.5</radius>
              </sphere>
            </geometry>
          </visual>
          <collision name='collision'>
            <geometry>
              <sphere>
                <radius>0.5</radius>
              </sphere>
            </geometry>
            <surface>
              <friction>
                <ode>
                  <mu>1</mu>
                  <mu2>1</mu2>
                  <slip1>0</slip1>
                  <slip2>0</slip2>
                </ode>
              </friction>
              <contact>
                <ode>
                  <soft_cfm>0</soft_cfm>
                  <soft_erp>0.2</soft_erp>
                  <kp>1e+13</kp>
                  <kd>1</kd>
                  <max_vel>0.01</max_vel>
                  <min_depth>0.01</min_depth>
                </ode>
              </contact>
            </surface>
          </collision>
        </link>

        <link name='right_wheel0'>
          <pose>0.554282 -0.625029 -0.025 -1.5707 0 0</pose>
          <inertial>
            <mass>2</mass>
            <inertia>
              <ixx>0.145833</ixx>
              <ixy>0</ixy>
              <ixz>0</ixz>
              <iyy>0.145833</iyy>
              <iyz>0</iyz>
              <izz>0.125</izz>
            </inertia>
          </inertial>
          <visual name='visual'>
            <geometry>
              <sphere>
                <radius>0.5</radius>
              </sphere>
            </geometry>
          </visual>
          <collision name='collision'>
            <geometry>
              <sphere>
                <radius>0.5</radius>
              </sphere>
            </geometry>
            <surface>
              <friction>
                <ode>
                  <mu>1</mu>
                  <mu2>1</mu2>
                  <slip1>0</slip1>
                  <slip2>0</slip2>
                </ode>
              </friction>
              <contact>
                <ode>
                  <soft_cfm>0</soft_cfm>
                  <soft_erp>0.2</soft_erp>
                  <kp>1e+13</kp>
                  <kd>1</kd>
                  <max_vel>0.01</max_vel>
                  <min_depth>0.01</min_depth>
                </ode>
              </contact>
            </surface>
          </collision>
        </link>

        <link name='left_wheel1'>
          <pose>-0.554283 0.625029 -0.025 -1.5707 0 0</pose>
          <inertial>
            <mass>2</mass>
            <inertia>
              <ixx>0.145833</ixx>
              <ixy>0</ixy>
              <ixz>0</ixz>
              <iyy>0.145833</iyy>
              <iyz>0</iyz>
              <izz>0.125</izz>
            </inertia>
          </inertial>
          <visual name='visual'>
            <geometry>
              <sphere>
                <radius>0.3</radius>
              </sphere>
            </geometry>
          </visual>
          <collision name='collision'>
            <geometry>
              <sphere>
                <radius>0.3</radius>
              </sphere>
            </geometry>
            <surface>
              <friction>
                <ode>
                  <mu>1</mu>
                  <mu2>1</mu2>
                  <slip1>0</slip1>
                  <slip2>0</slip2>
                </ode>
              </friction>
              <contact>
                <ode>
                  <soft_cfm>0</soft_cfm>
                  <soft_erp>0.2</soft_erp>
                  <kp>1e+13</kp>
                  <kd>1</kd>
                  <max_vel>0.01</max_vel>
                  <min_depth>0.01</min_depth>
                </ode>
              </contact>
            </surface>
          </collision>
        </link>

        <link name='right_wheel1'>
          <pose>-0.554282 -0.625029 -0.025 -1.5707 0 0</pose>
          <inertial>
            <mass>2</mass>
            <inertia>
              <ixx>0.145833</ixx>
              <ixy>0</ixy>
              <ixz>0</ixz>
              <iyy>0.145833</iyy>
              <iyz>0</iyz>
              <izz>0.125</izz>
            </inertia>
          </inertial>
          <visual name='visual'>
            <geometry>
              <sphere>
                <radius>0.3</radius>
              </sphere>
            </geometry>
          </visual>
          <collision name='collision'>
            <geometry>
              <sphere>
                <radius>0.3</radius>
              </sphere>
            </geometry>
            <surface>
              <friction>
                <ode>
                  <mu>1</mu>
                  <mu2>1</mu2>
                  <slip1>0</slip1>
                  <slip2>0</slip2>
                </ode>
              </friction>
              <contact>
                <ode>
                  <soft_cfm>0</soft_cfm>
                  <soft_erp>0.2</soft_erp>
                  <kp>1e+13</kp>
                  <kd>1</kd>
                  <max_vel>0.01</max_vel>
                  <min_depth>0.01</min_depth>
                </ode>
              </contact>
            </surface>
          </collision>
        </link>

        <link name='caster'>
          <pose>-0.957138 -0 -0.125 0 -0 0</pose>
          <inertial>
            <mass>1</mass>
            <inertia>
              <ixx>0.1</ixx>
              <ixy>0</ixy>
              <ixz>0</ixz>
              <iyy>0.1</iyy>
              <iyz>0</iyz>
              <izz>0.1</izz>
            </inertia>
          </inertial>
          <visual name='visual'>
            <geometry>
              <sphere>
                <radius>0.2</radius>
              </sphere>
            </geometry>
          </visual>
          <collision name='collision'>
            <geometry>
              <sphere>
                <radius>0.2</radius>
              </sphere>
            </geometry>
          </collision>
        </link>
        <link name="camera_link">
  <collision name="collision-base">
          <pose>0 0 0 0 0 0</pose>
          <geometry>
            <box>
              <size>0.15 0.15 0.15</size>
            </box>
          </geometry>
        </collision>
        <pose>0.7 0.3 0.53 0 0 0</pose>

        <visual name="visual-base">
          <pose>0 0 0 0 0 0</pose>
          <geometry>
            <box>
              <size>0.15 0.15 0.15</size>
            </box>
          </geometry>
          <material>
            <name>red</name>
          </material>
        </visual>

        <inertial>
          <mass>1e-5</mass>
          <pose>0 0 0 0 0 0</pose>
          <inertia>
            <ixx>1e-6</ixx>
            <ixy>0</ixy>
            <ixz>0</ixz>
            <iyy>1e-6</iyy>
            <iyz>0</iyz>
            <izz>1e-6</izz>
          </inertia>
        </inertial>
    <sensor type="camera" name="camera1">
      <update_rate>30.0</update_rate>
      <camera name="head">
        <horizontal_fov>1.3962634</horizontal_fov>
        <image>
          <width>800</width>
          <height>800</height>
          <format>R8G8B8</format>
        </image>
        <clip>
          <near>0.02</near>
          <far>300</far>
        </clip>
        <noise>
          <type>gaussian</type>
          <!-- Noise is sampled independently per pixel on each frame.
               That pixel's noise value is added to each of its color
               channels, which at that point lie in the range [0,1]. -->
          <mean>0.0</mean>
          <stddev>0.007</stddev>
        </noise>
      </camera>
      <plugin name="camera_controller" filename="libgazebo_ros_camera.so">
        <alwaysOn>true</alwaysOn>
        <updateRate>0.0</updateRate>
        <cameraName>rrbot/camera1</cameraName>
        <imageTopicName>image_raw</imageTopicName>
        <cameraInfoTopicName>camera_info</cameraInfoTopicName>
        <frameName>camera_link</frameName>
        <hackBaseline>0.07</hackBaseline>
        <distortionK1>0.0</distortionK1>
        <distortionK2>0.0</distortionK2>
        <distortionK3>0.0</distortionK3>
        <distortionT1>0.0</distortionT1>
        <distortionT2>0.0</distortionT2>
      </plugin>
    </sensor>
  </link>

        

        <joint name='left_wheel_joint0' type='revolute'>
          <parent>chassis</parent>
          <child>left_wheel0</child>
          <axis>
            <xyz>0 0 1</xyz>
            <limit>
              <lower>-1.79769e+308</lower>
              <upper>1.79769e+308</upper>
            </limit>
          </axis>
        </joint>

        <joint name='right_wheel_joint0' type='revolute'>
          <parent>chassis</parent>
          <child>right_wheel0</child>
          <axis>
            <xyz>0 0 1</xyz>
            <limit>
              <lower>-1.79769e+308</lower>
              <upper>1.79769e+308</upper>
            </limit>
          </axis>
        </joint>

        <joint name='left_wheel_joint1' type='revolute'>
          <parent>chassis</parent>
          <child>left_wheel1</child>
          <axis>
            <xyz>0 0 1</xyz>
            <limit>
              <lower>-1.79769e+308</lower>
              <upper>1.79769e+308</upper>
            </limit>
          </axis>
        </joint>

        <joint name='right_wheel_joint1' type='revolute'>
          <parent>chassis</parent>
          <child>right_wheel1</child>
          <axis>
            <xyz>0 0 1</xyz>
            <limit>
              <lower>-1.79769e+308</lower>
              <upper>1.79769e+308</upper>
            </limit>
          </axis>
        </joint>


        <joint name='caster_wheel' type='ball'>
          <parent>chassis</parent>
          <child>caster</child>
        </joint>
        <joint name="camera_joint" type="fixed">
        <axis>
          <xyz>0 1 0</xyz>
        </axis>
        <pose>1 0 2 0 0 0</pose>
        <parent>chassis</parent>
        <child>camera_link</child>
      </joint>

        <plugin name='skid_steer_drive' filename='libgazebo_ros_diff_drive.so'>

          <ros>
            <namespace>/demo</namespace>
            <remapping>cmd_vel:=cmd_demo</remapping>
            <remapping>odom:=odom_demo</remapping>
          </ros>

          <!-- Number of wheel pairs -->
          <num_wheel_pairs>2</num_wheel_pairs>
          
          <!-- wheels0 -->
          <left_joint>left_wheel_joint0</left_joint>
          <right_joint>right_wheel_joint0</right_joint>

          <!-- wheels1-->
          <left_joint>left_wheel_joint1</left_joint>
          <right_joint>right_wheel_joint1</right_joint>

          <!-- kinematics -->
          <wheel_separation>1.25</wheel_separation>
          <wheel_separation>1.25</wheel_separation>

          <wheel_diameter>1.0</wheel_diameter>
          <wheel_diameter>0.6</wheel_diameter>

          <!-- limits -->
          <max_wheel_torque>20</max_wheel_torque>
          <max_wheel_acceleration>1.0</max_wheel_acceleration>

          <!-- output -->
          <publish_odom>true</publish_odom>
          <publish_odom_tf>true</publish_odom_tf>
          <publish_wheel_tf>true</publish_wheel_tf>

          <odometry_frame>odom_demo</odometry_frame>
          <robot_base_frame>chassis</robot_base_frame>

        </plugin>

      </model>

    </world>
  </sdf>